Workbook

Sheet Échantillon
A1: Easy Checks – GRILLE D'ÉVALUATION
A2: Échantillon évalué
A3: Date ou période de réalisation de l’audit :
A4: Personne réalisant l’audit :
A5: Contexte de l’audit :
A6: Site audité :
A8: N° page | B8: Titre de la page | C8: URL | D8: Commentaire
A9: P01
A10: P02

Sheet P01
A1: Easy Checks – GRILLE D'ÉVALUATION
A2: =CONCATENATE(Échantillon!B9," : ",Échantillon!C9) -> :
A3: Section | B3: Sous-section | C3: Conformité | D3: Notes
A4: Chaque page web a-t-elle un titre de page pertinent ? | B4: Contient le nom du site | C4: NT
B5: Décrit le contenu ou la fonction de la page | C5: NT
B6: Précise quelle est l'étape en cours d'un processus | C6: NT
B7: Dans une série de résultats de recherche, précise quel est l'intervalle de résultats affichés. | C7: NT
A8: Chaque image porteuse d’information a-t-elle une alternative textuelle pertinente ? | B8: Vérifier que l'alternative textuelle est présente | C8: NT
B9: Vérifier que l'alternative textuelle est pertinente | C9: NT
A10: Chaque image de décoration est-elle correctement ignorée par les technologies d’assistance ? | B10: Vérifier que les images de décoration possèdent un attribut alt vide | C10: NT
B11: Vérifier que les images de décoration, quand elles le necessitent (SVG), sont ignorées par les outils d'assistance | C11: NT
A12: Dans chaque page web, l’information est-elle structurée par l’utilisation appropriée de titres ? | B12: La page doit être structurée selon un ordre logique | C12: NT
B13: Un titre doit décrire le contenu qu’il introduit | C13: NT
B14: Pas de titres "simulés" sans valeur sémantique | C14: NT
A15: Dans chaque page web, le contraste entre la couleur du texte et la couleur de son arrière-plan est-il suffisamment élevé ? les couleurs utilisées dans les composants d’interface sont-ils suffisamment élevé ? | B15: Ratio de contraste minimal de 4.5:1 pour les textes de moins de 24px, ou 18.5px en gras | C15: NT
B16: Ratio de contraste minimal de 3:1 pour les textes de plus de 24px ou 18.5px en gras | C16: NT
A17: Redimensionnement et zoom | B17: Zoom jusqu'à 200% - Redimentionnement à 320px de large - Tous les textes doivent pouvoir être agrandis - Les textes ou contenus ne doivent pas être coupés - Les textes ou contenus ne doivent pas se superposer - Tous les boutons, champs et éléments de contrôles doivent rester visibles et utilisables | C17: NT
A18: Focus et navigation au clavier | B18: La prise du focus doit être visible | C18: NT
B19: Un menu d'évitement est présent | C19: NT
B20: Tous les composants doivent fonctionner au clavier | C20: NT
A21: Formulaires | B21: Chaque champ est associé à son label | C21: NT
B22: Les labels sont visuellement accolés à leurs champs | C22: NT
B23: Les champs obligatoires sont indiqués et associés aux champs | C23: NT
B24: Les champs de même nature sont regroupés | C24: NT
B25: Le format attendu pour les champs est indiqués (avant validation) | C25: NT
B26: Un exemple de saisie valide est proposé | C26: NT
B27: Les champs correctement renseignés ne doivent pas être réinitialisés | C27: NT
B28: Les erreurs sont clairement indiquées et reliées aux champs | C28: NT
B29: Utilisation d'autocomplete | C29: NT
A30: Éléments en mouvements, clignotants ou flashant | B30: Les animations visuelles de plus de 5 secondes et les sons de plus de 3 secondes doivent être dotés de moyen de contrôles. | C30: NT
B31: Laisser à l'utilisateur le contrôle des animations | C31: NT
B32: Utilisation de prefers-reduced-motion pour déterminer si les animations sont activées | C32: NT
A33: Multimédia (vidéo, audio) | B33: Les éléments multimédias doivent pouvoir être contrôlés au clavier | C33: NT
B34: Vérifier la présence de sous-titre et de transcription | C34: NT
A35: Structure de l’information Vérifier la présence des landmarks | B35: Zone d’en-tête : <header role="banner"> | C35: NT
B36: Menu de navigation principal : <nav role="navigation”> | C36: NT
B37: Contenu principal : <main role="main"> | C37: NT
B38: Pied de page : <footer role="contentinfo"> | C38: NT
B39: Moteur de recherche : <search role="search> | C39: NT
A40: Langue de la page | B40: Vérifier la présence d'un attribut lang sur la balise html | C40: NT
...

Sheet P02
A1: Easy Checks – GRILLE D'ÉVALUATION
A2: =CONCATENATE(Échantillon!B10," : ",Échantillon!C10) -> :
A3: Section | B3: Sous-section | C3: Conformité | D3: Notes
A4: Chaque page web a-t-elle un titre de page pertinent ? | B4: Contient le nom du site | C4: NT
B5: Décrit le contenu ou la fonction de la page | C5: NT
B6: Précise quelle est l'étape en cours d'un processus | C6: NT
B7: Dans une série de résultats de recherche, précise quel est l'intervalle de résultats affichés. | C7: NT
A8: Chaque image porteuse d’information a-t-elle une alternative textuelle pertinente ? | B8: Vérifier que l'alternative textuelle est présente | C8: NT
B9: Vérifier que l'alternative textuelle est pertinente | C9: NT
A10: Chaque image de décoration est-elle correctement ignorée par les technologies d’assistance ? | B10: Vérifier que les images de décoration possèdent un attribut alt vide | C10: NT
B11: Vérifier que les images de décoration, quand elles le necessitent (SVG), sont ignorées par les outils d'assistance | C11: NT
A12: Dans chaque page web, l’information est-elle structurée par l’utilisation appropriée de titres ? | B12: La page doit être structurée selon un ordre logique | C12: NT
B13: Un titre doit décrire le contenu qu’il introduit | C13: NT
B14: Pas de titres "simulés" sans valeur sémantique | C14: NT
A15: Dans chaque page web, le contraste entre la couleur du texte et la couleur de son arrière-plan est-il suffisamment élevé ? les couleurs utilisées dans les composants d’interface sont-ils suffisamment élevé ? | B15: Ratio de contraste minimal de 4.5:1 pour les textes de moins de 24px, ou 18.5px en gras | C15: NT
B16: Ratio de contraste minimal de 3:1 pour les textes de plus de 24px ou 18.5px en gras | C16: NT
A17: Redimensionnement et zoom | B17: Zoom jusqu'à 200% - Redimentionnement à 320px de large - Tous les textes doivent pouvoir être agrandis - Les textes ou contenus ne doivent pas être coupés - Les textes ou contenus ne doivent pas se superposer - Tous les boutons, champs et éléments de contrôles doivent rester visibles et utilisables | C17: NT
A18: Focus et navigation au clavier | B18: La prise du focus doit être visible | C18: NT
B19: Un menu d'évitement est présent | C19: NT
B20: Tous les composants doivent fonctionner au clavier | C20: NT
A21: Formulaires | B21: Chaque champ est associé à son label | C21: NT
B22: Les labels sont visuellement accolés à leurs champs | C22: NT
B23: Les champs obligatoires sont indiqués et associés aux champs | C23: NT
B24: Les champs de même nature sont regroupés | C24: NT
B25: Le format attendu pour les champs est indiqués (avant validation) | C25: NT
B26: Un exemple de saisie valide est proposé | C26: NT
B27: Les champs correctement renseignés ne doivent pas être réinitialisés | C27: NT
B28: Les erreurs sont clairement indiquées et reliées aux champs | C28: NT
B29: Utilisation d'autocomplete | C29: NT
A30: Éléments en mouvements, clignotants ou flashant | B30: Les animations visuelles de plus de 5 secondes et les sons de plus de 3 secondes doivent être dotés de moyen de contrôles. | C30: NT
B31: Laisser à l'utilisateur le contrôle des animations | C31: NT
B32: Utilisation de prefers-reduced-motion pour déterminer si les animations sont activées | C32: NT
A33: Multimédia (vidéo, audio) | B33: Les éléments multimédias doivent pouvoir être contrôlés au clavier | C33: NT
B34: Vérifier la présence de sous-titre et de transcription | C34: NT
A35: Structure de l’information Vérifier la présence des landmarks | B35: Zone d’en-tête : <header role="banner"> | C35: NT
B36: Menu de navigation principal : <nav role="navigation”> | C36: NT
B37: Contenu principal : <main role="main"> | C37: NT
B38: Pied de page : <footer role="contentinfo"> | C38: NT
B39: Moteur de recherche : <search role="search> | C39: NT
A40: Langue de la page | B40: Vérifier la présence d'un attribut lang sur la balise html | C40: NT
...

Sheet Synthèse
D1: P01 | E1: P02 | F1: C | G1: NC | H1: NA | I1: NT
A2: Titre de la page | B2: =criteres!B2 -> Contient le nom du site | D2: ='P01'!C4 -> NT | E2: ='P02'!C4 -> NT | F2: =COUNTIF(D2:E2,"C") -> 0 | G2: =COUNTIF(D2:E2,"NC") -> 0 | H2: =COUNTIF(D2:E2,"NA") -> 0 | I2: ='P02'!C4 -> NT
A3: Titre de la page | B3: =criteres!B3 -> Décrit le contenu ou la fonction de la page | D3: ='P01'!C5 -> NT | E3: ='P02'!C5 -> NT | F3: =COUNTIF(D3:E3,"C") -> 0 | G3: =COUNTIF(D3:E3,"NC") -> 0 | H3: =COUNTIF(D3:E3,"NA") -> 0 | I3: =COUNTIF(D3:E3,"NT") -> 2
A4: Titre de la page | B4: =criteres!B4 -> Précise quelle est l'étape en cours d'un processus | D4: ='P01'!C6 -> NT | E4: ='P02'!C6 -> NT | F4: =COUNTIF(D4:E4,"C") -> 0 | G4: =COUNTIF(D4:E4,"NC") -> 0 | H4: =COUNTIF(D4:E4,"NA") -> 0 | I4: =COUNTIF(D4:E4,"NT") -> 2
A5: Titre de la page | B5: =criteres!B5 -> Dans une série de résultats de recherche, précise quel est l'intervalle de résultats affichés. | D5: ='P01'!C7 -> NT | E5: ='P02'!C7 -> NT | F5: =COUNTIF(D5:E5,"C") -> 0 | G5: =COUNTIF(D5:E5,"NC") -> 0 | H5: =COUNTIF(D5:E5,"NA") -> 0 | I5: =COUNTIF(D5:E5,"NT") -> 2
A6: Images | B6: =criteres!B6 -> Vérifier que l'alternative textuelle est présente | D6: ='P01'!C8 -> NT | E6: ='P02'!C8 -> NT | F6: =COUNTIF(D6:E6,"C") -> 0 | G6: =COUNTIF(D6:E6,"NC") -> 0 | H6: =COUNTIF(D6:E6,"NA") -> 0 | I6: =COUNTIF(D6:E6,"NT") -> 2
A7: Images | B7: =criteres!B7 -> Vérifier que l'alternative textuelle est pertinente | D7: ='P01'!C9 -> NT | E7: ='P02'!C9 -> NT | F7: =COUNTIF(D7:E7,"C") -> 0 | G7: =COUNTIF(D7:E7,"NC") -> 0 | H7: =COUNTIF(D7:E7,"NA") -> 0 | I7: =COUNTIF(D7:E7,"NT") -> 2
A8: Images | B8: =criteres!B8 -> Vérifier que les images de décoration possèdent un attribut alt vide | D8: ='P01'!C10 -> NT | E8: ='P02'!C10 -> NT | F8: =COUNTIF(D8:E8,"C") -> 0 | G8: =COUNTIF(D8:E8,"NC") -> 0 | H8: =COUNTIF(D8:E8,"NA") -> 0 | I8: =COUNTIF(D8:E8,"NT") -> 2
A9: Images | B9: =criteres!B9 -> Vérifier que les images de décoration, quand elles le necessitent (SVG), sont ignorées par les outils d'assistance | D9: ='P01'!C11 -> NT | E9: ='P02'!C11 -> NT | F9: =COUNTIF(D9:E9,"C") -> 0 | G9: =COUNTIF(D9:E9,"NC") -> 0 | H9: =COUNTIF(D9:E9,"NA") -> 0 | I9: =COUNTIF(D9:E9,"NT") -> 2
A10: Titres | B10: =criteres!B10 -> La page doit être structurée selon un ordre logique | D10: ='P01'!C12 -> NT | E10: ='P02'!C12 -> NT | F10: =COUNTIF(D10:E10,"C") -> 0 | G10: =COUNTIF(D10:E10,"NC") -> 0 | H10: =COUNTIF(D10:E10,"NA") -> 0 | I10: =COUNTIF(D10:E10,"NT") -> 2
A11: Titres | B11: =criteres!B11 -> Un titre doit décrire le contenu qu’il introduit | D11: ='P01'!C13 -> NT | E11: ='P02'!C13 -> NT | F11: =COUNTIF(D11:E11,"C") -> 0 | G11: =COUNTIF(D11:E11,"NC") -> 0 | H11: =COUNTIF(D11:E11,"NA") -> 0 | I11: =COUNTIF(D11:E11,"NT") -> 2
A12: Titres | B12: =criteres!B12 -> Pas de titres "simulés" sans valeur sémantique | D12: ='P01'!C14 -> NT | E12: ='P02'!C14 -> NT | F12: =COUNTIF(D12:E12,"C") -> 0 | G12: =COUNTIF(D12:E12,"NC") -> 0 | H12: =COUNTIF(D12:E12,"NA") -> 0 | I12: =COUNTIF(D12:E12,"NT") -> 2
A13: Contrastes | B13: =criteres!B13 -> Ratio de contraste minimal de 4.5:1 pour les textes de moins de 24px, ou 18.5px en gras | D13: ='P01'!C15 -> NT | E13: ='P02'!C15 -> NT | F13: =COUNTIF(D13:E13,"C") -> 0 | G13: =COUNTIF(D13:E13,"NC") -> 0 | H13: =COUNTIF(D13:E13,"NA") -> 0 | I13: =COUNTIF(D13:E13,"NT") -> 2
A14: Contrastes | B14: =criteres!B14 -> Ratio de contraste minimal de 3:1 pour les textes de plus de 24px ou 18.5px en gras | D14: ='P01'!C16 -> NT | E14: ='P02'!C16 -> NT | F14: =COUNTIF(D14:E14,"C") -> 0 | G14: =COUNTIF(D14:E14,"NC") -> 0 | H14: =COUNTIF(D14:E14,"NA") -> 0 | I14: =COUNTIF(D14:E14,"NT") -> 2
... A38: Langue | B38: =criteres!B38 -> Vérifier la présence d'un attribut lang sur la balise html | D38: ='P01'!C40 -> NT | E38: ='P02'!C40 -> NT | F38: =COUNTIF(D38:E38,"C") -> 0 | G38: =COUNTIF(D38:E38,"NC") -> 0 | H38: =COUNTIF(D38:E38,"NA") -> 0 | I38: =COUNTIF(D38:E38,"NT") -> 2

Sheet criteres
A1: Section | B1: Sous-section | C1: Conformité | D1: Notes
A2: Chaque page web a-t-elle un titre de page pertinent ? | B2: Contient le nom du site | C2: NT
B3: Décrit le contenu ou la fonction de la page | C3: NT
B4: Précise quelle est l'étape en cours d'un processus | C4: NT
B5: Dans une série de résultats de recherche, précise quel est l'intervalle de résultats affichés. | C5: NT
A6: Chaque image porteuse d’information a-t-elle une alternative textuelle pertinente ? | B6: Vérifier que l'alternative textuelle est présente | C6: NT
B7: Vérifier que l'alternative textuelle est pertinente | C7: NT
A8: Chaque image de décoration est-elle correctement ignorée par les technologies d’assistance ? | B8: Vérifier que les images de décoration possèdent un attribut alt vide | C8: NT
B9: Vérifier que les images de décoration, quand elles le necessitent (SVG), sont ignorées par les outils d'assistance | C9: NT
A10: Dans chaque page web, l’information est-elle structurée par l’utilisation appropriée de titres ? | B10: La page doit être structurée selon un ordre logique | C10: NT
B11: Un titre doit décrire le contenu qu’il introduit | C11: NT
B12: Pas de titres "simulés" sans valeur sémantique | C12: NT
A13: Dans chaque page web, le contraste entre la couleur du texte et la couleur de son arrière-plan est-il suffisamment élevé ? les couleurs utilisées dans les composants d’interface sont-ils suffisamment élevé ? | B13: Ratio de contraste minimal de 4.5:1 pour les textes de moins de 24px, ou 18.5px en gras | C13: NT
B14: Ratio de contraste minimal de 3:1 pour les textes de plus de 24px ou 18.5px en gras | C14: NT
A15: Redimensionnement et zoom | B15: Zoom jusqu'à 200% - Redimentionnement à 320px de large - Tous les textes doivent pouvoir être agrandis - Les textes ou contenus ne doivent pas être coupés - Les textes ou contenus ne doivent pas se superposer - Tous les boutons, champs et éléments de contrôles doivent rester visibles et utilisables | C15: NT
A16: Focus et navigation au clavier | B16: La prise du focus doit être visible | C16: NT
B17: Un menu d'évitement est présent | C17: NT
B18: Tous les composants doivent fonctionner au clavier | C18: NT
A19: Formulaires | B19: Chaque champ est associé à son label | C19: NT
B20: Les labels sont visuellement accolés à leurs champs | C20: NT
B21: Les champs obligatoires sont indiqués et associés aux champs | C21: NT
B22: Les champs de même nature sont regroupés | C22: NT
B23: Le format attendu pour les champs est indiqués (avant validation) | C23: NT
B24: Un exemple de saisie valide est proposé | C24: NT
B25: Les champs correctement renseignés ne doivent pas être réinitialisés | C25: NT
B26: Les erreurs sont clairement indiquées et reliées aux champs | C26: NT
B27: Utilisation d'autocomplete | C27: NT
A28: Éléments en mouvements, clignotants ou flashant | B28: Les animations visuelles de plus de 5 secondes et les sons de plus de 3 secondes doivent être dotés de moyen de contrôles. | C28: NT
B29: Laisser à l'utilisateur le contrôle des animations | C29: NT
B30: Utilisation de prefers-reduced-motion pour déterminer si les animations sont activées | C30: NT
A31: Multimédia (vidéo, audio) | B31: Les éléments multimédias doivent pouvoir être contrôlés au clavier | C31: NT
B32: Vérifier la présence de sous-titre et de transcription | C32: NT
A33: Structure de l’information Vérifier la présence des landmarks | B33: Zone d’en-tête : <header role="banner"> | C33: NT
B34: Menu de navigation principal : <nav role="navigation”> | C34: NT
B35: Contenu principal : <main role="main"> | C35: NT
B36: Pied de page : <footer role="contentinfo"> | C36: NT
B37: Moteur de recherche : <search role="search> | C37: NT
A38: Langue de la page | B38: Vérifier la présence d'un attribut lang sur la balise html | C38: NT
B39: Vérifier la présence d'une balise avec un attribut lang englobant chaque changement de langue | C39: NT
